Workbook

Sheet Read_me
A1: How to order
A2: 1. On the BOM sheet set "Boards to build" (B4) and review the yellow Use alternate / Include / Spares cells.
A3: 2. Open the DigiKey_Upload sheet. Delete rows whose Quantity is 0 (optional cable parts are off by default), then save it as CSV or copy the rows.
A4: 3. On digikey.com use BOM Manager (Upload a BOM) or Cart > Quick Add > "Upload a list", and map: Quantity, Digi-Key Part Number, Customer Reference. digikey_upload_1_board.csv (next to this workbook) is the same list for 1 board with the default choices.
A5: 4. Red stock figures on the BOM sheet mean the chosen part has less stock than you are ordering.
A7: Decisions before ordering
A8: U5, NFC reader: ST25R3916-AQWT is out of stock at Digi-Key (the ST25R3916B is not due until 2028). The in-stock ST25R3917-AQWT is pin-compatible but has no capacitive-sensor wake-up, no automatic antenna tuning and no card emulation. It works for this reader if the firmware uses inductive wake-up and J5/J6 stay unconnected. Set U5 "Use alternate" = Y to order it, or source the ST25R3916 elsewhere.
A9: Y2 + C6/C7, 32.768 kHz: no 4 pF-load 3.2x1.5 mm crystal is stocked, so Y2 is a 6 pF part and C6/C7 were changed to 8.2 pF in the schematic (2026-09-26).
A10: R6, charge current: 1 kΩ sets 1 A, above the 500 mA a USB-C sink with 5.1 kΩ CC resistors may draw. The 2 kΩ alternate gives 500 mA.
A11: C20/C21/C36, 10 µF: only 178 of the Samsung part are in stock; switch to the Yageo alternate if that runs out.
A13: Not included
A14: The PCB itself, the Li-ion cell (with a JST XA plug), the vibration motor, the optional PN532 breakout module, solder paste and a JST XA crimp tool. J5/J6 (solder pads) and AE3 (etched antenna) are PCB features, not parts.
... A18: Checked 2026-09-26. Each row has a Digi-Key search link (column AA) for re-checking stock and price.

Sheet BOM
A1: Card Attendance System: Bill of Materials (Digi-Key)
A2: Source: PCB/Attendance Management System.kicad_sch. Part numbers, stock and prices read from digikey.com on 2026-09-26; stock and prices change daily, so re-check before ordering.
A4: Boards to build | B4: 1
A5: Edit only the yellow cells: Boards to build, Use alternate (Y/N), Include (Y/N), Spares. Order qty, the part to order and the cost are formulas.
A7: Item | B7: Designators | C7: Qty / board | D7: Value | E7: Description | F7: Package | G7: Manufacturer | H7: MPN | I7: Digi-Key PN | J7: DK stock (2026-09-26) | K7: Unit price (USD) | L7: Price at qty | M7: Use alternate (Y/N) | N7: Alt. manufacturer | O7: Alt. MPN | P7: Alt. Digi-Key PN | Q7: Alt. DK stock | R7: Alt. unit price (USD) | S7: Include (Y/N) | T7: Spares | U7: Order qty | V7: Order: manufacturer | W7: Order: MPN | X7: Order: Digi-Key PN | Y7: Est. cost (USD) | Z7: Notes | AA7: Digi-Key link
A8: 1 | B8: C1,C3,C8,C11,C22,C23,C24,C25,C28,C29,C30,C34 | C8: 12 | D8: 100n | E8: Capacitor, ceramic, 100 nF 50 V X7R ±10% | F8: 0805 | G8: Samsung Electro-Mechanics | H8: CL21B104KBCNNNC | I8: 1276-1003-1-ND | J8: 4581382 | K8: 0.045 | L8: 10 | M8: N | S8: Y | T8: 3 | U8: =IF(S8="Y",C8*$B$4+T8,0) | V8: =IF(M8="Y",N8,G8)&"" | W8: =IF(M8="Y",O8,H8)&"" | X8: =IF(M8="Y",P8,I8)&"" | Y8: =U8*IF(M8="Y",R8,K8) | Z8: Schematic asks X7R 16 V; 50 V part has less DC-bias loss. | AA8: =IF(W8="","",HYPERLINK("https://www.digikey.com/en/products/result?keywords="&W8,"open"))
A9: 2 | B9: C2,C35 | C9: 2 | D9: 4.7u | E9: Capacitor, ceramic, 4.7 µF 25 V X5R ±10% | F9: 0805 | G9: Samsung Electro-Mechanics | H9: CL21A475KACLRNC | I9: 1276-2415-1-ND | J9: 190853 | K9: 0.137 | L9: 10 | M9: N | S9: Y | T9: 2 | U9: =IF(S9="Y",C9*$B$4+T9,0) | V9: =IF(M9="Y",N9,G9)&"" | W9: =IF(M9="Y",O9,H9)&"" | X9: =IF(M9="Y",P9,I9)&"" | Y9: =U9*IF(M9="Y",R9,K9) | Z9: Covers C2 (10 V) and C35 (16 V) with one 25 V part. CL21A475KAQNNNE is out of stock. | AA9: =IF(W9="","",HYPERLINK("https://www.digikey.com/en/products/result?keywords="&W9,"open"))
A10: 3 | B10: C4 | C10: 1 | D10: 10n | E10: Capacitor, ceramic, 10 nF 50 V X7R ±10% | F10: 0805 | G10: Samsung Electro-Mechanics | H10: CL21B103KBANNNC | I10: 1276-1015-1-ND | J10: 2107628 | K10: 0.044 | L10: 10 | M10: N | S10: Y | T10: 2 | U10: =IF(S10="Y",C10*$B$4+T10,0) | V10: =IF(M10="Y",N10,G10)&"" | W10: =IF(M10="Y",O10,H10)&"" | X10: =IF(M10="Y",P10,I10)&"" | Y10: =U10*IF(M10="Y",R10,K10) | AA10: =IF(W10="","",HYPERLINK("https://www.digikey.com/en/products/result?keywords="&W10,"open"))
A11: 4 | B11: C5,C33 | C11: 2 | D11: 1u | E11: Capacitor, ceramic, 1 µF 25 V X7R ±10% | F11: 0805 | G11: KEMET | H11: C0805C105K3RACTU | I11: 399-C0805C105K3RACTUCT-ND | J11: 373194 | K11: 0.109 | L11: 10 | M11: N | S11: Y | T11: 2 | U11: =IF(S11="Y",C11*$B$4+T11,0) | V11: =IF(M11="Y",N11,G11)&"" | W11: =IF(M11="Y",O11,H11)&"" | X11: =IF(M11="Y",P11,I11)&"" | Y11: =U11*IF(M11="Y",R11,K11) | Z11: Samsung CL21B105K parts are out of stock. | AA11: =IF(W11="","",HYPERLINK("https://www.digikey.com/en/products/result?keywords="&W11,"open"))
A12: 5 | B12: C6,C7 | C12: 2 | D12: 8.2p | E12: Capacitor, ceramic, 8.2 pF 50 V C0G ±0.25 pF (LSE load caps) | F12: 0805 | G12: KEMET | H12: C0805C829C5GACTU | I12: 399-C0805C829C5GACTUCT-ND | J12: 3279 | K12: 0.372 | L12: 10 | M12: N | S12: Y | T12: 2 | U12: =IF(S12="Y",C12*$B$4+T12,0) | V12: =IF(M12="Y",N12,G12)&"" | W12: =IF(M12="Y",O12,H12)&"" | X12: =IF(M12="Y",P12,I12)&"" | Y12: =U12*IF(M12="Y",R12,K12) | Z12: Y2 has CL = 6 pF (no 4 pF 3.2x1.5 mm crystal is stocked), which needs 8.2 pF load caps: CL = C/2 + ~2 pF stray. Changed from 4.3p in the schematic on 2026-09-26. | AA12: =IF(W12="","",HYPERLINK("https://www.digikey.com/en/products/result?keywords="&W12,"open"))
A13: 6 | B13: C9,C10 | C13: 2 | D13: 15p | E13: Capacitor, ceramic, 15 pF 50 V C0G ±5% (27.12 MHz load caps) | F13: 0805 | G13: KEMET | H13: C0805C150J5GACTU | I13: 399-C0805C150J5GACTUCT-ND | J13: 28868 | K13: 0.16 | L13: 10 | M13: N | S13: Y | T13: 2 | U13: =IF(S13="Y",C13*$B$4+T13,0) | V13: =IF(M13="Y",N13,G13)&"" | W13: =IF(M13="Y",O13,H13)&"" | X13: =IF(M13="Y",P13,I13)&"" | Y13: =U13*IF(M13="Y",R13,K13) | Z13: Samsung CL21C150JBANNNC is obsolete. | AA13: =IF(W13="","",HYPERLINK("https://www.digikey.com/en/products/result?keywords="&W13,"open"))
A14: 7 | B14: C12,C13,C38,C39 | C14: 4 | D14: 150p | E14: Capacitor, ceramic, 150 pF 50 V C0G ±5% | F14: 0805 | G14: KEMET | H14: C0805C151J5GACTU | I14: 399-C0805C151J5GACTUCT-ND | J14: 62894 | K14: 0.08 | L14: 10 | M14: N | S14: Y | T14: 2 | U14: =IF(S14="Y",C14*$B$4+T14,0) | V14: =IF(M14="Y",N14,G14)&"" | W14: =IF(M14="Y",O14,H14)&"" | X14: =IF(M14="Y",P14,I14)&"" | Y14: =U14*IF(M14="Y",R14,K14) | Z14: EMC filter (C12/C13) and RX divider (C38/C39). | AA14: =IF(W14="","",HYPERLINK("https://www.digikey.com/en/products/result?keywords="&W14,"open"))
A15: 8 | B15: C15,C37 | C15: 2 | D15: 10p | E15: Capacitor, ceramic, 10 pF 50 V C0G ±5% | F15: 0805 | G15: KEMET | H15: C0805C100J5GACTU | I15: 399-C0805C100J5GAC7800CT-ND | J15: 215055 | K15: 0.076 | L15: 10 | M15: N | S15: Y | T15: 2 | U15: =IF(S15="Y",C15*$B$4+T15,0) | V15: =IF(M15="Y",N15,G15)&"" | W15: =IF(M15="Y",O15,H15)&"" | X15: =IF(M15="Y",P15,I15)&"" | Y15: =U15*IF(M15="Y",R15,K15) | Z15: RX divider series caps. Digi-Key number really ends GAC7800CT-ND. | AA15: =IF(W15="","",HYPERLINK("https://www.digikey.com/en/products/result?keywords="&W15,"open"))
A16: 9 | B16: C16,C17 | C16: 2 | D16: 68p | E16: Capacitor, ceramic, 68 pF 50 V C0G ±5% (series matching) | F16: 0805 | G16: KEMET | H16: C0805C680J5GACTU | I16: 399-C0805C680J5GACTUCT-ND | J16: 20555 | K16: 0.106 | L16: 10 | M16: N | S16: Y | T16: 4 | U16: =IF(S16="Y",C16*$B$4+T16,0) | V16: =IF(M16="Y",N16,G16)&"" | W16: =IF(M16="Y",O16,H16)&"" | X16: =IF(M16="Y",P16,I16)&"" | Y16: =U16*IF(M16="Y",R16,K16) | Z16: Matching values change when the antenna is tuned; spares allow a retune. | AA16: =IF(W16="","",HYPERLINK("https://www.digikey.com/en/products/result?keywords="&W16,"open"))
A17: 10 | B17: C18,C19 | C17: 2 | D17: 270p | E17: Capacitor, ceramic, 270 pF 50 V C0G ±5% (parallel matching) | F17: 0805 | G17: KEMET | H17: C0805C271J5GACTU | I17: 399-C0805C271J5GACTUCT-ND | J17: 147889 | K17: 0.216 | L17: 10 | M17: N | S17: Y | T17: 4 | U17: =IF(S17="Y",C17*$B$4+T17,0) | V17: =IF(M17="Y",N17,G17)&"" | W17: =IF(M17="Y",O17,H17)&"" | X17: =IF(M17="Y",P17,I17)&"" | Y17: =U17*IF(M17="Y",R17,K17) | Z17: As above. | AA17: =IF(W17="","",HYPERLINK("https://www.digikey.com/en/products/result?keywords="&W17,"open"))
A18: 11 | B18: C20,C21,C36 | C18: 3 | D18: 10u | E18: Capacitor, ceramic, 10 µF 25 V X5R ±10% | F18: 0805 | G18: Samsung Electro-Mechanics | H18: CL21A106KAFN3NE | I18: 1276-2890-1-ND | J18: 178 | K18: 0.158 | L18: 10 | M18: N | N18: YAGEO | O18: CC0805KKX5R6BB106 | P18: 311-1460-1-ND | Q18: 5598 | R18: 0.341 | S18: Y | T18: 1 | U18: =IF(S18="Y",C18*$B$4+T18,0) | V18: =IF(M18="Y",N18,G18)&"" | W18: =IF(M18="Y",O18,H18)&"" | X18: =IF(M18="Y",P18,I18)&"" | Y18: =U18*IF(M18="Y",R18,K18) | Z18: Only 178 in stock (enough for ~50 boards). Every other 10 µF 0805 checked (Samsung, Murata, TDK, KEMET) was out of stock. The alternate is 10 V, fine on the 4.2 V BAT+ rail. | AA18: =IF(W18="","",HYPERLINK("https://www.digikey.com/en/products/result?keywords="&W18,"open"))
A19: 12 | B19: C26,C27,C31,C32 | C19: 4 | D19: 2.2u | E19: Capacitor, ceramic, 2.2 µF 25 V X7R ±10% | F19: 0805 | G19: Samsung Electro-Mechanics | H19: CL21B225KAFNNNE | I19: 1276-2954-1-ND | J19: 390169 | K19: 0.087 | L19: 10 | M19: N | S19: Y | T19: 2 | U19: =IF(S19="Y",C19*$B$4+T19,0) | V19: =IF(M19="Y",N19,G19)&"" | W19: =IF(M19="Y",O19,H19)&"" | X19: =IF(M19="Y",P19,I19)&"" | Y19: =U19*IF(M19="Y",R19,K19) | AA19: =IF(W19="","",HYPERLINK("https://www.digikey.com/en/products/result?keywords="&W19,"open"))
A20: 13 | B20: D1,D5 | C20: 2 | D20: RED | E20: LED, red 631 nm, clear lens | F20: 0805 | G20: Lite-On Inc. | H20: LTST-C170KRKT | I20: 160-1415-1-ND | J20: 436448 | K20: 0.18 | L20: 1 | M20: N | S20: Y | T20: 1 | U20: =IF(S20="Y",C20*$B$4+T20,0) | V20: =IF(M20="Y",N20,G20)&"" | W20: =IF(M20="Y",O20,H20)&"" | X20: =IF(M20="Y",P20,I20)&"" | Y20: =U20*IF(M20="Y",R20,K20) | Z20: Check the cathode mark against the footprint. | AA20: =IF(W20="","",HYPERLINK("https://www.digikey.com/en/products/result?keywords="&W20,"open"))
A21: 14 | B21: D2,D3,D6 | C21: 3 | D21: GREEN | E21: LED, green 571 nm, clear lens | F21: 0805 | G21: Lite-On Inc. | H21: LTST-C170KGKT | I21: 160-1414-1-ND | J21: 477688 | K21: 0.19 | L21: 1 | M21: N | S21: Y | T21: 1 | U21: =IF(S21="Y",C21*$B$4+T21,0) | V21: =IF(M21="Y",N21,G21)&"" | W21: =IF(M21="Y",O21,H21)&"" | X21: =IF(M21="Y",P21,I21)&"" | Y21: =U21*IF(M21="Y",R21,K21) | AA21: =IF(W21="","",HYPERLINK("https://www.digikey.com/en/products/result?keywords="&W21,"open"))
A22: 15 | B22: D4 | C22: 1 | D22: SS14 | E22: Diode, Schottky 40 V 1 A (motor flyback) | F22: SMA (DO-214AC) | G22: Vishay General Semiconductor | H22: SS14-E3/61T | I22: SS14-E3/61TGICT-ND | J22: 141918 | K22: 0.47 | L22: 1 | M22: N | S22: Y | T22: 0 | U22: =IF(S22="Y",C22*$B$4+T22,0) | V22: =IF(M22="Y",N22,G22)&"" | W22: =IF(M22="Y",O22,H22)&"" | X22: =IF(M22="Y",P22,I22)&"" | Y22: =U22*IF(M22="Y",R22,K22) | AA22: =IF(W22="","",HYPERLINK("https://www.digikey.com/en/products/result?keywords="&W22,"open"))
A23: 16 | B23: FB1,FB2 | C23: 2 | D23: 600R@100MHz | E23: Ferrite bead, 600 Ω @ 100 MHz, 300 mA, 0.52 Ω DCR | F23: 0402 | G23: Murata Electronics | H23: BLM15AG601SN1D | I23: 490-1006-1-ND | J23: 1148672 | K23: 0.1 | L23: 1 | M23: N | S23: Y | T23: 2 | U23: =IF(S23="Y",C23*$B$4+T23,0) | V23: =IF(M23="Y",N23,G23)&"" | W23: =IF(M23="Y",O23,H23)&"" | X23: =IF(M23="Y",P23,I23)&"" | Y23: =U23*IF(M23="Y",R23,K23) | AA23: =IF(W23="","",HYPERLINK("https://www.digikey.com/en/products/result?keywords="&W23,"open"))
A24: 17 | B24: J1 | C24: 1 | D24: USB-C | E24: Connector, USB-C receptacle, USB 2.0, 16-pin, SMT right angle | F24: GCT USB4110 | G24: GCT | H24: USB4110-GF-A | I24: 2073-USB4110-GF-A-1-ND | J24: 145796 | K24: 1.27 | L24: 1 | M24: N | S24: Y | T24: 0 | U24: =IF(S24="Y",C24*$B$4+T24,0) | V24: =IF(M24="Y",N24,G24)&"" | W24: =IF(M24="Y",O24,H24)&"" | X24: =IF(M24="Y",P24,I24)&"" | Y24: =U24*IF(M24="Y",R24,K24) | AA24: =IF(W24="","",HYPERLINK("https://www.digikey.com/en/products/result?keywords="&W24,"open"))
A25: 18 | B25: J2 | C25: 1 | D25: BATTERY | E25: Connector header, JST XA, 2-pos 2.50 mm, vertical, shrouded, THT | F25: JST B02B-XASK-1 | G25: JST Sales America Inc. | H25: B02B-XASK-1 | I25: 455-B02B-XASK-1-ND | J25: 12098 | K25: 0.16 | L25: 1 | M25: N | S25: Y | T25: 0 | U25: =IF(S25="Y",C25*$B$4+T25,0) | V25: =IF(M25="Y",N25,G25)&"" | W25: =IF(M25="Y",O25,H25)&"" | X25: =IF(M25="Y",P25,I25)&"" | Y25: =U25*IF(M25="Y",R25,K25) | Z25: Mating cable parts are listed at the end (optional). | AA25: =IF(W25="","",HYPERLINK("https://www.digikey.com/en/products/result?keywords="&W25,"open"))
A26: 19 | B26: J3 | C26: 1 | D26: SWD | E26: Pin header, 1x4, 2.54 mm, vertical, THT | F26: 1x04 P2.54 | G26: Sullins Connector Solutions | H26: PREC004SAAN-RC | I26: 35-PREC004SAAN-RC-ND | J26: 42330 | K26: 0.1 | L26: 1 | M26: N | S26: Y | T26: 0 | U26: =IF(S26="Y",C26*$B$4+T26,0) | V26: =IF(M26="Y",N26,G26)&"" | W26: =IF(M26="Y",O26,H26)&"" | X26: =IF(M26="Y",P26,I26)&"" | Y26: =U26*IF(M26="Y",R26,K26) | AA26: =IF(W26="","",HYPERLINK("https://www.digikey.com/en/products/result?keywords="&W26,"open"))
A27: 20 | B27: J4 | C27: 1 | D27: VIB_MOTOR | E27: Pin header, 1x2, 2.54 mm, vertical, THT | F27: 1x02 P2.54 | G27: Sullins Connector Solutions | H27: PREC002SAAN-RC | I27: 35-PREC002SAAN-RC-ND | J27: 55276 | K27: 0.1 | L27: 1 | M27: N | S27: Y | T27: 0 | U27: =IF(S27="Y",C27*$B$4+T27,0) | V27: =IF(M27="Y",N27,G27)&"" | W27: =IF(M27="Y",O27,H27)&"" | X27: =IF(M27="Y",P27,I27)&"" | Y27: =U27*IF(M27="Y",R27,K27) | Z27: The vibration motor itself is not in this BOM. | AA27: =IF(W27="","",HYPERLINK("https://www.digikey.com/en/products/result?keywords="&W27,"open"))
A28: 21 | B28: J5,J6 | C28: 2 | D28: CSO / CSI | E28: Solder pads for the capacitive wake-up electrode wires (PCB feature) | F28: SolderWirePad 1x2 mm | M28: N | S28: N | T28: 0 | U28: =IF(S28="Y",C28*$B$4+T28,0) | V28: =IF(M28="Y",N28,G28)&"" | W28: =IF(M28="Y",O28,H28)&"" | X28: =IF(M28="Y",P28,I28)&"" | Y28: =U28*IF(M28="Y",R28,K28) | Z28: No part to buy. Leave unconnected if U5 is the ST25R3917 alternate (pins 2/25 must be NC). | AA28: =IF(W28="","",HYPERLINK("https://www.digikey.com/en/products/result?keywords="&W28,"open"))
A29: 22 | B29: J7 | C29: 1 | D29: PN532 | E29: Socket header, 1x8, 2.54 mm, female, vertical, THT | F29: 1x08 P2.54 | G29: Sullins Connector Solutions | H29: PPTC081LFBN-RC | I29: S7006-ND | J29: 29560 | K29: 0.58 | L29: 1 | M29: N | S29: Y | T29: 0 | U29: =IF(S29="Y",C29*$B$4+T29,0) | V29: =IF(M29="Y",N29,G29)&"" | W29: =IF(M29="Y",O29,H29)&"" | X29: =IF(M29="Y",P29,I29)&"" | Y29: =U29*IF(M29="Y",R29,K29) | Z29: PN532 backup-reader module is not in this BOM. | AA29: =IF(W29="","",HYPERLINK("https://www.digikey.com/en/products/result?keywords="&W29,"open"))
A30: 23 | B30: L3,L4 | C30: 2 | D30: 470nH | E30: Inductor, wirewound ceramic, 470 nH ±5%, 250 mA, 1.76 Ω DCR | F30: 0805 | G30: Coilcraft | H30: 0805CS-471XJRC | I30: 2457-0805CS-471XJRC-ND | J30: 10591 | K30: 1.34 | L30: 1 | M30: N | S30: Y | T30: 0 | U30: =IF(S30="Y",C30*$B$4+T30,0) | V30: =IF(M30="Y",N30,G30)&"" | W30: =IF(M30="Y",O30,H30)&"" | X30: =IF(M30="Y",P30,I30)&"" | Y30: =U30*IF(M30="Y",R30,K30) | Z30: EMC filter carries the full TX current; 250 mA / 1.76 Ω is the best stocked 470 nH 0805. A 1210 part (e.g. Murata LQH32C) would lose less power but needs a new footprint. | AA30: =IF(W30="","",HYPERLINK("https://www.digikey.com/en/products/result?keywords="&W30,"open"))
A31: 24 | B31: Q1 | C31: 1 | D31: AO3400A | E31: MOSFET, N-ch 30 V 5.7 A (motor driver) | F31: SOT-23 | G31: Alpha & Omega Semiconductor | H31: AO3400A | I31: 785-1000-1-ND | J31: 303749 | K31: 0.52 | L31: 1 | M31: N | S31: Y | T31: 0 | U31: =IF(S31="Y",C31*$B$4+T31,0) | V31: =IF(M31="Y",N31,G31)&"" | W31: =IF(M31="Y",O31,H31)&"" | X31: =IF(M31="Y",P31,I31)&"" | Y31: =U31*IF(M31="Y",R31,K31) | AA31: =IF(W31="","",HYPERLINK("https://www.digikey.com/en/products/result?keywords="&W31,"open"))
A32: 25 | B32: R1,R2 | C32: 2 | D32: 5.1k | E32: Resistor, 5.1 kΩ ±1% 1/8 W thick film (USB-C CC) | F32: 0805 | G32: Stackpole Electronics | H32: RMCF0805FT5K10 | I32: RMCF0805FT5K10CT-ND | J32: 101761 | K32: 0.027 | L32: 10 | M32: N | S32: Y | T32: 2 | U32: =IF(S32="Y",C32*$B$4+T32,0) | V32: =IF(M32="Y",N32,G32)&"" | W32: =IF(M32="Y",O32,H32)&"" | X32: =IF(M32="Y",P32,I32)&"" | Y32: =U32*IF(M32="Y",R32,K32) | Z32: Yageo RC0805FR-075K1L is out of stock. | AA32: =IF(W32="","",HYPERLINK("https://www.digikey.com/en/products/result?keywords="&W32,"open"))
A33: 26 | B33: R3,R4,R5,R9,R10 | C33: 5 | D33: 470R | E33: Resistor, 470 Ω ±1% 1/8 W thick film (LED series) | F33: 0805 | G33: Stackpole Electronics | H33: RMCF0805FT470R | I33: RMCF0805FT470RCT-ND | J33: 106645 | K33: 0.027 | L33: 10 | M33: N | S33: Y | T33: 2 | U33: =IF(S33="Y",C33*$B$4+T33,0) | V33: =IF(M33="Y",N33,G33)&"" | W33: =IF(M33="Y",O33,H33)&"" | X33: =IF(M33="Y",P33,I33)&"" | Y33: =U33*IF(M33="Y",R33,K33) | AA33: =IF(W33="","",HYPERLINK("https://www.digikey.com/en/products/result?keywords="&W33,"open"))
A34: 27 | B34: R6 | C34: 1 | D34: 1k | E34: Resistor, 1 kΩ ±1% 1/8 W (MCP73833 PROG: sets charge current) | F34: 0805 | G34: Stackpole Electronics | H34: RMCF0805FT1K00 | I34: RMCF0805FT1K00CT-ND | J34: 320655 | K34: 0.027 | L34: 10 | M34: N | N34: Stackpole Electronics | O34: RMCF0805FT2K00 | P34: RMCF0805FT2K00CT-ND | Q34: 119534 | R34: 0.027 | S34: Y | T34: 2 | U34: =IF(S34="Y",C34*$B$4+T34,0) | V34: =IF(M34="Y",N34,G34)&"" | W34: =IF(M34="Y",O34,H34)&"" | X34: =IF(M34="Y",P34,I34)&"" | Y34: =U34*IF(M34="Y",R34,K34) | Z34: 1 kΩ = 1 A charge current: more than a USB-C sink with 5.1 kΩ Rd may draw (500 mA) and hot for the MSOP-10. Set Use alternate = Y for 2 kΩ (500 mA) after changing the schematic. | AA34: =IF(W34="","",HYPERLINK("https://www.digikey.com/en/products/result?keywords="&W34,"open"))
A35: 28 | B35: R7,R8,R11,R12,R20 | C35: 5 | D35: 10k | E35: Resistor, 10 kΩ ±1% 1/8 W thick film | F35: 0805 | G35: Stackpole Electronics | H35: RMCF0805FT10K0 | I35: RMCF0805FT10K0CT-ND | J35: 3852513 | K35: 0.027 | L35: 10 | M35: N | S35: Y | T35: 2 | U35: =IF(S35="Y",C35*$B$4+T35,0) | V35: =IF(M35="Y",N35,G35)&"" | W35: =IF(M35="Y",O35,H35)&"" | X35: =IF(M35="Y",P35,I35)&"" | Y35: =U35*IF(M35="Y",R35,K35) | AA35: =IF(W35="","",HYPERLINK("https://www.digikey.com/en/products/result?keywords="&W35,"open"))
A36: 29 | B36: R15 | C36: 1 | D36: 1.5k | E36: Resistor, 1.5 kΩ ±1% 1/8 W (antenna damping) | F36: 0805 | G36: Stackpole Electronics | H36: RMCF0805FT1K50 | I36: RMCF0805FT1K50CT-ND | J36: 149568 | K36: 0.027 | L36: 10 | M36: N | S36: Y | T36: 2 | U36: =IF(S36="Y",C36*$B$4+T36,0) | V36: =IF(M36="Y",N36,G36)&"" | W36: =IF(M36="Y",O36,H36)&"" | X36: =IF(M36="Y",P36,I36)&"" | Y36: =U36*IF(M36="Y",R36,K36) | Z36: Damping value may change during antenna tuning. | AA36: =IF(W36="","",HYPERLINK("https://www.digikey.com/en/products/result?keywords="&W36,"open"))
A37: 30 | B37: R16,R18,R19 | C37: 3 | D37: 4.7M | E37: Resistor, 4.7 MΩ ±1% 1/8 W (battery and VBUS dividers) | F37: 0805 | G37: Stackpole Electronics | H37: RMCF0805FT4M70 | I37: RMCF0805FT4M70CT-ND | J37: 12637 | K37: 0.031 | L37: 10 | M37: N | S37: Y | T37: 2 | U37: =IF(S37="Y",C37*$B$4+T37,0) | V37: =IF(M37="Y",N37,G37)&"" | W37: =IF(M37="Y",O37,H37)&"" | X37: =IF(M37="Y",P37,I37)&"" | Y37: =U37*IF(M37="Y",R37,K37) | AA37: =IF(W37="","",HYPERLINK("https://www.digikey.com/en/products/result?keywords="&W37,"open"))
A38: 31 | B38: R17 | C38: 1 | D38: 2.7M | E38: Resistor, 2.7 MΩ ±1% 1/8 W (battery divider low leg) | F38: 0805 | G38: Stackpole Electronics | H38: RMCF0805FT2M70 | I38: RMCF0805FT2M70CT-ND | J38: 6211 | K38: 0.031 | L38: 10 | M38: N | S38: Y | T38: 2 | U38: =IF(S38="Y",C38*$B$4+T38,0) | V38: =IF(M38="Y",N38,G38)&"" | W38: =IF(M38="Y",O38,H38)&"" | X38: =IF(M38="Y",P38,I38)&"" | Y38: =U38*IF(M38="Y",R38,K38) | AA38: =IF(W38="","",HYPERLINK("https://www.digikey.com/en/products/result?keywords="&W38,"open"))
A39: 32 | B39: R21,R22 | C39: 2 | D39: 0 | E39: Resistor, 0 Ω jumper (antenna feed) | F39: 0805 | G39: Stackpole Electronics | H39: RMCF0805ZT0R00 | I39: RMCF0805ZT0R00CT-ND | J39: 3287189 | K39: 0.01 | L39: 10 | M39: N | S39: Y | T39: 2 | U39: =IF(S39="Y",C39*$B$4+T39,0) | V39: =IF(M39="Y",N39,G39)&"" | W39: =IF(M39="Y",O39,H39)&"" | X39: =IF(M39="Y",P39,I39)&"" | Y39: =U39*IF(M39="Y",R39,K39) | AA39: =IF(W39="","",HYPERLINK("https://www.digikey.com/en/products/result?keywords="&W39,"open"))
A40: 33 | B40: SW1,SW2,SW3 | C40: 3 | D40: RST / BOOT0 / POWER | E40: Tactile switch, SPST-NO, 180 gf, 2.5 mm height, SMT | F40: C&K PTS636 | G40: C&K | H40: PTS636SM25SMTR LFS | I40: CKN12321-1-ND | J40: 20227 | K40: 0.29 | L40: 1 | M40: N | S40: Y | T40: 0 | U40: =IF(S40="Y",C40*$B$4+T40,0) | V40: =IF(M40="Y",N40,G40)&"" | W40: =IF(M40="Y",O40,H40)&"" | X40: =IF(M40="Y",P40,I40)&"" | Y40: =U40*IF(M40="Y",R40,K40) | Z40: Footprint is PTS636Sx25SMTRLFS; SM = 180 gf actuation. | AA40: =IF(W40="","",HYPERLINK("https://www.digikey.com/en/products/result?keywords="&W40,"open"))
A41: 34 | B41: TH1 | C41: 1 | D41: 10k NTC | E41: NTC thermistor, 10 kΩ ±5%, B25/85 = 3977 K, leaded bead | F41: THT, vertical | G41: Vishay BC Components | H41: NTCLE100E3103JB0 | I41: BC2301-ND | J41: 10220 | K41: 0.6 | L41: 1 | M41: N | S41: Y | T41: 0 | U41: =IF(S41="Y",C41*$B$4+T41,0) | V41: =IF(M41="Y",N41,G41)&"" | W41: =IF(M41="Y",O41,H41)&"" | X41: =IF(M41="Y",P41,I41)&"" | Y41: =U41*IF(M41="Y",R41,K41) | Z41: Flexible leads; bend to the 1.9 mm footprint pitch. | AA41: =IF(W41="","",HYPERLINK("https://www.digikey.com/en/products/result?keywords="&W41,"open"))
A42: 35 | B42: U1 | C42: 1 | D42: STM32L432KBU6 | E42: MCU, Arm Cortex-M4F 80 MHz, 128 kB flash, 64 kB RAM | F42: UFQFPN-32 5x5 | G42: STMicroelectronics | H42: STM32L432KBU6 | L42: 1 | M42: N | S42: Y | T42: 0 | U42: =IF(S42="Y",C42*$B$4+T42,0) | V42: =IF(M42="Y",N42,G42)&"" | W42: =IF(M42="Y",O42,H42)&"" | X42: =IF(M42="Y",P42,I42)&"" | Y42: =U42*IF(M42="Y",R42,K42) | Z42: 128 kB part, as on the schematic and in production/bom.csv; the firmware keeps code (72 kB) and the log (56 kB) within 128 kB. Digi-Key number, stock and price not looked up yet: search the MPN before ordering (cost counts 0 until then). | AA42: =IF(W42="","",HYPERLINK("https://www.digikey.com/en/products/result?keywords="&W42,"open"))
...

Sheet DigiKey_Upload
A1: Quantity | B1: Digi-Key Part Number | C1: Manufacturer Part Number | D1: Manufacturer | E1: Customer Reference
A2: =BOM!U8 | B2: =BOM!X8 | C2: =BOM!W8 | D2: =BOM!V8 | E2: =BOM!B8
A3: =BOM!U9 | B3: =BOM!X9 | C3: =BOM!W9 | D3: =BOM!V9 | E3: =BOM!B9
A4: =BOM!U10 | B4: =BOM!X10 | C4: =BOM!W10 | D4: =BOM!V10 | E4: =BOM!B10
A5: =BOM!U11 | B5: =BOM!X11 | C5: =BOM!W11 | D5: =BOM!V11 | E5: =BOM!B11
A6: =BOM!U12 | B6: =BOM!X12 | C6: =BOM!W12 | D6: =BOM!V12 | E6: =BOM!B12
A7: =BOM!U13 | B7: =BOM!X13 | C7: =BOM!W13 | D7: =BOM!V13 | E7: =BOM!B13
A8: =BOM!U14 | B8: =BOM!X14 | C8: =BOM!W14 | D8: =BOM!V14 | E8: =BOM!B14
A9: =BOM!U15 | B9: =BOM!X15 | C9: =BOM!W15 | D9: =BOM!V15 | E9: =BOM!B15
A10: =BOM!U16 | B10: =BOM!X16 | C10: =BOM!W16 | D10: =BOM!V16 | E10: =BOM!B16
A11: =BOM!U17 | B11: =BOM!X17 | C11: =BOM!W17 | D11: =BOM!V17 | E11: =BOM!B17
A12: =BOM!U18 | B12: =BOM!X18 | C12: =BOM!W18 | D12: =BOM!V18 | E12: =BOM!B18
A13: =BOM!U19 | B13: =BOM!X19 | C13: =BOM!W19 | D13: =BOM!V19 | E13: =BOM!B19
... A21: =BOM!U27 | B21: =BOM!X27 | C21: =BOM!W27 | D21: =BOM!V27 | E21: =BOM!B27
A22: =BOM!U29 | B22: =BOM!X29 | C22: =BOM!W29 | D22: =BOM!V29 | E22: =BOM!B29
A23: =BOM!U30 | B23: =BOM!X30 | C23: =BOM!W30 | D23: =BOM!V30 | E23: =BOM!B30
A24: =BOM!U31 | B24: =BOM!X31 | C24: =BOM!W31 | D24: =BOM!V31 | E24: =BOM!B31
A25: =BOM!U32 | B25: =BOM!X32 | C25: =BOM!W32 | D25: =BOM!V32 | E25: =BOM!B32
A26: =BOM!U33 | B26: =BOM!X33 | C26: =BOM!W33 | D26: =BOM!V33 | E26: =BOM!B33
A27: =BOM!U34 | B27: =BOM!X34 | C27: =BOM!W34 | D27: =BOM!V34 | E27: =BOM!B34
A28: =BOM!U35 | B28: =BOM!X35 | C28: =BOM!W35 | D28: =BOM!V35 | E28: =BOM!B35
A29: =BOM!U36 | B29: =BOM!X36 | C29: =BOM!W36 | D29: =BOM!V36 | E29: =BOM!B36
A30: =BOM!U37 | B30: =BOM!X37 | C30: =BOM!W37 | D30: =BOM!V37 | E30: =BOM!B37
A31: =BOM!U38 | B31: =BOM!X38 | C31: =BOM!W38 | D31: =BOM!V38 | E31: =BOM!B38
A32: =BOM!U39 | B32: =BOM!X39 | C32: =BOM!W39 | D32: =BOM!V39 | E32: =BOM!B39
A33: =BOM!U40 | B33: =BOM!X40 | C33: =BOM!W40 | D33: =BOM!V40 | E33: =BOM!B40
... A41: =BOM!U48 | B41: =BOM!X48 | C41: =BOM!W48 | D41: =BOM!V48 | E41: =BOM!B48
A42: =BOM!U50 | B42: =BOM!X50 | C42: =BOM!W50 | D42: =BOM!V50 | E42: =BOM!B50
A43: =BOM!U51 | B43: =BOM!X51 | C43: =BOM!W51 | D43: =BOM!V51 | E43: =BOM!B51
