Workbook

Sheet Read_me
A1: Two ways to use this BOM
A2: Every orderable symbol in the schematic now carries a hidden LCSC field with the number used here, so the Fabrication Toolkit fills the LCSC column of production/bom.csv itself once the board is updated from the schematic.
A3: JLCPCB assembly: upload jlcpcb_bom.csv (next to this workbook, same as the JLCPCB_BOM sheet) with production/positions.csv from the Fabrication Toolkit. U1 is out of stock there, so mark it "do not place" and solder it yourself, or send one to JLCPCB as a consigned part. J2, J3, J4, J7 and TH1 are through-hole: add JLCPCB's through-hole assembly or solder them by hand. Check part rotations in JLCPCB's placement preview before you pay.
A4: Buying parts from LCSC to build by hand: set "Boards to build" (B4) on the BOM sheet, review the yellow cells, then copy the LCSC_Order sheet into LCSC's BOM tool (lcsc.com > BOM Tool) or add the parts to the cart. Delete rows whose Quantity is 0 (the optional battery-cable parts are off by default). LCSC sells most passives in minimum lots of 10 to 100, so the order quantities are rounded up to those.
A5: Red stock figures on the BOM sheet mean the chosen part has less stock than you need.
A7: JLCPCB library types
A8: Basic parts are already loaded on JLCPCB's machines. Extended parts each carry a one-off loading fee per part type per order; Preferred extended parts have that fee waived on Economic assembly. The BOM sheet counts the Extended types you are ordering. Passives use Basic parts wherever one exists in the right value and 0805 size; the small C0G values, 4.7 MΩ and 2.7 MΩ are not in the Basic library.
A10: Decisions before ordering
A11: U1 is the 128 kB STM32L432KBU6 (C2928224), as in production/bom.csv: since 2026-10-07 the firmware keeps its code and attendance log within 128 kB. Its stock, price and JLCPCB library type have not been re-read; check them before ordering.
A12: Y2 + C6/C7: no 4 pF-load 3.2x1.5 mm crystal is stocked, so Y2 is a 6 pF Epson FC-135 and C6/C7 were changed to 8.2 pF in the schematic (2026-09-26).
A13: R6: 1 kΩ sets a 1 A charge current, above the 500 mA a USB-C sink with 5.1 kΩ CC resistors may draw. The 2 kΩ alternate gives 500 mA.
A14: U5: ST25R3916-AQWT is in stock at LCSC (about 100) although Digi-Key has none. Order early if you need more than a few boards.
... A21: Checked 2026-09-26. Each row has an LCSC link (last column) for re-checking stock and price.

Sheet BOM
A1: Card Attendance System: Bill of Materials (LCSC / JLCPCB)
A2: Source: PCB/Attendance Management System.kicad_sch. Part numbers, stock, minimum order quantities, prices and JLCPCB library types read from lcsc.com and jlcpcb.com on 2026-09-26; they change daily, so re-check before ordering.
A4: Boards to build | B4: 1
A5: Edit only the yellow cells: Boards to build, Use alternate (Y/N), Include (Y/N), Spares. Needed qty, LCSC order qty (rounded up to the LCSC minimum lot), the part to order and the cost are formulas.
A7: Item | B7: Designators | C7: Qty / board | D7: Value | E7: Description | F7: Footprint | G7: Manufacturer | H7: MPN | I7: LCSC # | J7: JLCPCB library | K7: LCSC stock (2026-09-26) | L7: JLCPCB stock | M7: LCSC min / multiple | N7: Unit price at min (USD) | O7: Use alternate (Y/N) | P7: Alt. value | Q7: Alt. manufacturer | R7: Alt. MPN | S7: Alt. LCSC # | T7: Alt. JLCPCB library | U7: Alt. LCSC stock | V7: Alt. JLCPCB stock | W7: Alt. min / multiple | X7: Alt. unit price (USD) | Y7: Include (Y/N) | Z7: Spares | AA7: Needed qty | AB7: LCSC order qty | AC7: Order: value | AD7: Order: manufacturer | AE7: Order: MPN | AF7: Order: LCSC # | AG7: Order: JLCPCB library | AH7: Boards the JLCPCB stock covers | AI7: Est. cost (USD) | AJ7: Notes | AK7: LCSC link
A8: 1 | B8: C1,C3,C8,C11,C22,C23,C24,C25,C28,C29,C30,C34 | C8: 12 | D8: 100n | E8: Capacitor, 100 nF 50 V X7R ±10% | F8: 0805 | G8: YAGEO | H8: CC0805KRX7R9BB104 | I8: C49678 | J8: Basic | K8: 9771320 | L8: 18198779 | M8: 20 | N8: 0.0192 | O8: N | Y8: Y | Z8: 0 | AA8: =IF(Y8="Y",C8*$B$4+Z8,0) | AB8: =IF(AA8=0,0,MAX(IF(O8="Y",W8,M8),CEILING(AA8,IF(O8="Y",W8,M8)))) | AC8: =IF(O8="Y",P8,D8)&"" | AD8: =IF(O8="Y",Q8,G8)&"" | AE8: =IF(O8="Y",R8,H8)&"" | AF8: =IF(O8="Y",S8,I8)&"" | AG8: =IF(O8="Y",T8,J8)&"" | AH8: =IF(OR(AF8="",Y8<>"Y"),"",INT(IF(O8="Y",V8,L8)/C8)) | AI8: =AB8*IF(O8="Y",X8,N8) | AJ8: Schematic asks X7R 16 V; the 50 V Basic part has less DC-bias loss. | AK8: =IF(AF8="","",HYPERLINK("https://www.lcsc.com/product-detail/"&AF8&".html","open"))
A9: 2 | B9: C2,C35 | C9: 2 | D9: 4.7u | E9: Capacitor, 4.7 µF 25 V X5R ±10% | F9: 0805 | G9: Samsung Electro-Mechanics | H9: CL21A475KAQNNNE | I9: C1779 | J9: Basic | K9: 1968760 | L9: 2946783 | M9: 20 | N9: 0.0348 | O9: N | Y9: Y | Z9: 0 | AA9: =IF(Y9="Y",C9*$B$4+Z9,0) | AB9: =IF(AA9=0,0,MAX(IF(O9="Y",W9,M9),CEILING(AA9,IF(O9="Y",W9,M9)))) | AC9: =IF(O9="Y",P9,D9)&"" | AD9: =IF(O9="Y",Q9,G9)&"" | AE9: =IF(O9="Y",R9,H9)&"" | AF9: =IF(O9="Y",S9,I9)&"" | AG9: =IF(O9="Y",T9,J9)&"" | AH9: =IF(OR(AF9="",Y9<>"Y"),"",INT(IF(O9="Y",V9,L9)/C9)) | AI9: =AB9*IF(O9="Y",X9,N9) | AJ9: One 25 V part covers C2 (10 V) and C35 (16 V). | AK9: =IF(AF9="","",HYPERLINK("https://www.lcsc.com/product-detail/"&AF9&".html","open"))
A10: 3 | B10: C4 | C10: 1 | D10: 10n | E10: Capacitor, 10 nF 50 V X7R ±10% | F10: 0805 | G10: Samsung Electro-Mechanics | H10: CL21B103KBANNNC | I10: C1710 | J10: Basic | K10: 1184600 | L10: 2362717 | M10: 50 | N10: 0.0116 | O10: N | Y10: Y | Z10: 0 | AA10: =IF(Y10="Y",C10*$B$4+Z10,0) | AB10: =IF(AA10=0,0,MAX(IF(O10="Y",W10,M10),CEILING(AA10,IF(O10="Y",W10,M10)))) | AC10: =IF(O10="Y",P10,D10)&"" | AD10: =IF(O10="Y",Q10,G10)&"" | AE10: =IF(O10="Y",R10,H10)&"" | AF10: =IF(O10="Y",S10,I10)&"" | AG10: =IF(O10="Y",T10,J10)&"" | AH10: =IF(OR(AF10="",Y10<>"Y"),"",INT(IF(O10="Y",V10,L10)/C10)) | AI10: =AB10*IF(O10="Y",X10,N10) | AK10: =IF(AF10="","",HYPERLINK("https://www.lcsc.com/product-detail/"&AF10&".html","open"))
A11: 4 | B11: C5,C33 | C11: 2 | D11: 1u | E11: Capacitor, 1 µF 50 V X7R ±10% | F11: 0805 | G11: Samsung Electro-Mechanics | H11: CL21B105KBFNNNE | I11: C28323 | J11: Basic | K11: 271530 | L11: 2506668 | M11: 10 | N11: 0.0403 | O11: N | Y11: Y | Z11: 0 | AA11: =IF(Y11="Y",C11*$B$4+Z11,0) | AB11: =IF(AA11=0,0,MAX(IF(O11="Y",W11,M11),CEILING(AA11,IF(O11="Y",W11,M11)))) | AC11: =IF(O11="Y",P11,D11)&"" | AD11: =IF(O11="Y",Q11,G11)&"" | AE11: =IF(O11="Y",R11,H11)&"" | AF11: =IF(O11="Y",S11,I11)&"" | AG11: =IF(O11="Y",T11,J11)&"" | AH11: =IF(OR(AF11="",Y11<>"Y"),"",INT(IF(O11="Y",V11,L11)/C11)) | AI11: =AB11*IF(O11="Y",X11,N11) | AK11: =IF(AF11="","",HYPERLINK("https://www.lcsc.com/product-detail/"&AF11&".html","open"))
A12: 5 | B12: C6,C7 | C12: 2 | D12: 8.2p | E12: Capacitor, 8.2 pF 50 V C0G ±0.25 pF (32.768 kHz load caps) | F12: 0805 | G12: FH | H12: 0805CG8R2C500NT | I12: C1840 | J12: Extended | K12: 34100 | L12: 34887 | M12: 50 | N12: 0.011 | O12: N | Y12: Y | Z12: 0 | AA12: =IF(Y12="Y",C12*$B$4+Z12,0) | AB12: =IF(AA12=0,0,MAX(IF(O12="Y",W12,M12),CEILING(AA12,IF(O12="Y",W12,M12)))) | AC12: =IF(O12="Y",P12,D12)&"" | AD12: =IF(O12="Y",Q12,G12)&"" | AE12: =IF(O12="Y",R12,H12)&"" | AF12: =IF(O12="Y",S12,I12)&"" | AG12: =IF(O12="Y",T12,J12)&"" | AH12: =IF(OR(AF12="",Y12<>"Y"),"",INT(IF(O12="Y",V12,L12)/C12)) | AI12: =AB12*IF(O12="Y",X12,N12) | AJ12: Y2 has CL = 6 pF, so C6/C7 need about 2 x (6 - 2 pF stray) = 8 pF. Changed from 4.3p in the schematic on 2026-09-26. | AK12: =IF(AF12="","",HYPERLINK("https://www.lcsc.com/product-detail/"&AF12&".html","open"))
A13: 6 | B13: C9,C10 | C13: 2 | D13: 15p | E13: Capacitor, 15 pF 50 V C0G ±5% (27.12 MHz load caps) | F13: 0805 | G13: YAGEO | H13: CC0805JRNPO9BN150 | I13: C107110 | J13: Preferred ext. | K13: 118450 | L13: 165907 | M13: 50 | N13: 0.0095 | O13: N | Y13: Y | Z13: 0 | AA13: =IF(Y13="Y",C13*$B$4+Z13,0) | AB13: =IF(AA13=0,0,MAX(IF(O13="Y",W13,M13),CEILING(AA13,IF(O13="Y",W13,M13)))) | AC13: =IF(O13="Y",P13,D13)&"" | AD13: =IF(O13="Y",Q13,G13)&"" | AE13: =IF(O13="Y",R13,H13)&"" | AF13: =IF(O13="Y",S13,I13)&"" | AG13: =IF(O13="Y",T13,J13)&"" | AH13: =IF(OR(AF13="",Y13<>"Y"),"",INT(IF(O13="Y",V13,L13)/C13)) | AI13: =AB13*IF(O13="Y",X13,N13) | AK13: =IF(AF13="","",HYPERLINK("https://www.lcsc.com/product-detail/"&AF13&".html","open"))
A14: 7 | B14: C12,C13,C38,C39 | C14: 4 | D14: 150p | E14: Capacitor, 150 pF 50 V C0G ±5% | F14: 0805 | G14: YAGEO | H14: CC0805JRNPO9BN151 | I14: C107111 | J14: Extended | K14: 183200 | L14: 184665 | M14: 50 | N14: 0.0081 | O14: N | Y14: Y | Z14: 0 | AA14: =IF(Y14="Y",C14*$B$4+Z14,0) | AB14: =IF(AA14=0,0,MAX(IF(O14="Y",W14,M14),CEILING(AA14,IF(O14="Y",W14,M14)))) | AC14: =IF(O14="Y",P14,D14)&"" | AD14: =IF(O14="Y",Q14,G14)&"" | AE14: =IF(O14="Y",R14,H14)&"" | AF14: =IF(O14="Y",S14,I14)&"" | AG14: =IF(O14="Y",T14,J14)&"" | AH14: =IF(OR(AF14="",Y14<>"Y"),"",INT(IF(O14="Y",V14,L14)/C14)) | AI14: =AB14*IF(O14="Y",X14,N14) | AJ14: EMC filter (C12/C13) and RX divider (C38/C39). | AK14: =IF(AF14="","",HYPERLINK("https://www.lcsc.com/product-detail/"&AF14&".html","open"))
A15: 8 | B15: C15,C37 | C15: 2 | D15: 10p | E15: Capacitor, 10 pF 50 V C0G ±5% (RX divider) | F15: 0805 | G15: YAGEO | H15: CC0805JRNPO9BN100 | I15: C107107 | J15: Extended | K15: 467700 | L15: 494538 | M15: 100 | N15: 0.0184 | O15: N | Y15: Y | Z15: 0 | AA15: =IF(Y15="Y",C15*$B$4+Z15,0) | AB15: =IF(AA15=0,0,MAX(IF(O15="Y",W15,M15),CEILING(AA15,IF(O15="Y",W15,M15)))) | AC15: =IF(O15="Y",P15,D15)&"" | AD15: =IF(O15="Y",Q15,G15)&"" | AE15: =IF(O15="Y",R15,H15)&"" | AF15: =IF(O15="Y",S15,I15)&"" | AG15: =IF(O15="Y",T15,J15)&"" | AH15: =IF(OR(AF15="",Y15<>"Y"),"",INT(IF(O15="Y",V15,L15)/C15)) | AI15: =AB15*IF(O15="Y",X15,N15) | AK15: =IF(AF15="","",HYPERLINK("https://www.lcsc.com/product-detail/"&AF15&".html","open"))
A16: 9 | B16: C16,C17 | C16: 2 | D16: 68p | E16: Capacitor, 68 pF 50 V C0G ±5% (series matching) | F16: 0805 | G16: YAGEO | H16: CC0805JRNPO9BN680 | I16: C107120 | J16: Extended | K16: 45050 | L16: 47387 | M16: 50 | N16: 0.0101 | O16: N | Y16: Y | Z16: 0 | AA16: =IF(Y16="Y",C16*$B$4+Z16,0) | AB16: =IF(AA16=0,0,MAX(IF(O16="Y",W16,M16),CEILING(AA16,IF(O16="Y",W16,M16)))) | AC16: =IF(O16="Y",P16,D16)&"" | AD16: =IF(O16="Y",Q16,G16)&"" | AE16: =IF(O16="Y",R16,H16)&"" | AF16: =IF(O16="Y",S16,I16)&"" | AG16: =IF(O16="Y",T16,J16)&"" | AH16: =IF(OR(AF16="",Y16<>"Y"),"",INT(IF(O16="Y",V16,L16)/C16)) | AI16: =AB16*IF(O16="Y",X16,N16) | AJ16: Matching values change when the antenna is tuned; the LCSC minimum lot leaves spares for a retune. | AK16: =IF(AF16="","",HYPERLINK("https://www.lcsc.com/product-detail/"&AF16&".html","open"))
A17: 10 | B17: C18,C19 | C17: 2 | D17: 270p | E17: Capacitor, 270 pF 100 V C0G ±5% (parallel matching) | F17: 0805 | G17: YAGEO | H17: CC0805JRNPO0BN271 | I17: C107106 | J17: Extended | K17: 15500 | L17: 15534 | M17: 50 | N17: 0.016 | O17: N | Y17: Y | Z17: 0 | AA17: =IF(Y17="Y",C17*$B$4+Z17,0) | AB17: =IF(AA17=0,0,MAX(IF(O17="Y",W17,M17),CEILING(AA17,IF(O17="Y",W17,M17)))) | AC17: =IF(O17="Y",P17,D17)&"" | AD17: =IF(O17="Y",Q17,G17)&"" | AE17: =IF(O17="Y",R17,H17)&"" | AF17: =IF(O17="Y",S17,I17)&"" | AG17: =IF(O17="Y",T17,J17)&"" | AH17: =IF(OR(AF17="",Y17<>"Y"),"",INT(IF(O17="Y",V17,L17)/C17)) | AI17: =AB17*IF(O17="Y",X17,N17) | AJ17: As above. | AK17: =IF(AF17="","",HYPERLINK("https://www.lcsc.com/product-detail/"&AF17&".html","open"))
A18: 11 | B18: C20,C21,C36 | C18: 3 | D18: 10u | E18: Capacitor, 10 µF 25 V X5R ±10% | F18: 0805 | G18: Samsung Electro-Mechanics | H18: CL21A106KAYNNNE | I18: C15850 | J18: Basic | K18: 1512600 | L18: 5574591 | M18: 20 | N18: 0.0798 | O18: N | Y18: Y | Z18: 0 | AA18: =IF(Y18="Y",C18*$B$4+Z18,0) | AB18: =IF(AA18=0,0,MAX(IF(O18="Y",W18,M18),CEILING(AA18,IF(O18="Y",W18,M18)))) | AC18: =IF(O18="Y",P18,D18)&"" | AD18: =IF(O18="Y",Q18,G18)&"" | AE18: =IF(O18="Y",R18,H18)&"" | AF18: =IF(O18="Y",S18,I18)&"" | AG18: =IF(O18="Y",T18,J18)&"" | AH18: =IF(OR(AF18="",Y18<>"Y"),"",INT(IF(O18="Y",V18,L18)/C18)) | AI18: =AB18*IF(O18="Y",X18,N18) | AK18: =IF(AF18="","",HYPERLINK("https://www.lcsc.com/product-detail/"&AF18&".html","open"))
A19: 12 | B19: C26,C27,C31,C32 | C19: 4 | D19: 2.2u | E19: Capacitor, 2.2 µF 50 V X5R ±10% | F19: 0805 | G19: Samsung Electro-Mechanics | H19: CL21A225KBQNNNE | I19: C377773 | J19: Basic | K19: 194170 | L19: 685779 | M19: 10 | N19: 0.0536 | O19: N | Y19: Y | Z19: 0 | AA19: =IF(Y19="Y",C19*$B$4+Z19,0) | AB19: =IF(AA19=0,0,MAX(IF(O19="Y",W19,M19),CEILING(AA19,IF(O19="Y",W19,M19)))) | AC19: =IF(O19="Y",P19,D19)&"" | AD19: =IF(O19="Y",Q19,G19)&"" | AE19: =IF(O19="Y",R19,H19)&"" | AF19: =IF(O19="Y",S19,I19)&"" | AG19: =IF(O19="Y",T19,J19)&"" | AH19: =IF(OR(AF19="",Y19<>"Y"),"",INT(IF(O19="Y",V19,L19)/C19)) | AI19: =AB19*IF(O19="Y",X19,N19) | AK19: =IF(AF19="","",HYPERLINK("https://www.lcsc.com/product-detail/"&AF19&".html","open"))
A20: 13 | B20: D1,D5 | C20: 2 | D20: RED | E20: LED, red 630 nm | F20: 0805 | G20: NATIONSTAR | H20: NCD0805R1 | I20: C84256 | J20: Basic | K20: 4428400 | L20: 5303999 | M20: 50 | N20: 0.0135 | O20: N | Y20: Y | Z20: 0 | AA20: =IF(Y20="Y",C20*$B$4+Z20,0) | AB20: =IF(AA20=0,0,MAX(IF(O20="Y",W20,M20),CEILING(AA20,IF(O20="Y",W20,M20)))) | AC20: =IF(O20="Y",P20,D20)&"" | AD20: =IF(O20="Y",Q20,G20)&"" | AE20: =IF(O20="Y",R20,H20)&"" | AF20: =IF(O20="Y",S20,I20)&"" | AG20: =IF(O20="Y",T20,J20)&"" | AH20: =IF(OR(AF20="",Y20<>"Y"),"",INT(IF(O20="Y",V20,L20)/C20)) | AI20: =AB20*IF(O20="Y",X20,N20) | AJ20: Check the cathode mark against the footprint. | AK20: =IF(AF20="","",HYPERLINK("https://www.lcsc.com/product-detail/"&AF20&".html","open"))
A21: 14 | B21: D2,D3,D6 | C21: 3 | D21: GREEN | E21: LED, yellow-green 571 nm (AlInGaP, Vf ~2 V) | F21: 0805 | G21: LITEON | H21: LTST-C170KGKT | I21: C98221 | J21: Extended | K21: 254200 | L21: 254219 | M21: 20 | N21: 0.0315 | O21: N | Y21: Y | Z21: 0 | AA21: =IF(Y21="Y",C21*$B$4+Z21,0) | AB21: =IF(AA21=0,0,MAX(IF(O21="Y",W21,M21),CEILING(AA21,IF(O21="Y",W21,M21)))) | AC21: =IF(O21="Y",P21,D21)&"" | AD21: =IF(O21="Y",Q21,G21)&"" | AE21: =IF(O21="Y",R21,H21)&"" | AF21: =IF(O21="Y",S21,I21)&"" | AG21: =IF(O21="Y",T21,J21)&"" | AH21: =IF(OR(AF21="",Y21<>"Y"),"",INT(IF(O21="Y",V21,L21)/C21)) | AI21: =AB21*IF(O21="Y",X21,N21) | AJ21: Not the Basic green (KT-0805G, C2297): that is a 525 nm InGaN LED with Vf 2.6-3.1 V, which barely lights on D6 (PA2 at 3.3 V through 470 R). | AK21: =IF(AF21="","",HYPERLINK("https://www.lcsc.com/product-detail/"&AF21&".html","open"))
A22: 15 | B22: D4 | C22: 1 | D22: SS14 | E22: Diode, Schottky 40 V 1 A (motor flyback) | F22: D_SMA | G22: MDD(Microdiode Semiconductor) | H22: SS14 | I22: C2480 | J22: Basic | K22: 890450 | L22: 1205634 | M22: 50 | N22: 0.0192 | O22: N | Y22: Y | Z22: 0 | AA22: =IF(Y22="Y",C22*$B$4+Z22,0) | AB22: =IF(AA22=0,0,MAX(IF(O22="Y",W22,M22),CEILING(AA22,IF(O22="Y",W22,M22)))) | AC22: =IF(O22="Y",P22,D22)&"" | AD22: =IF(O22="Y",Q22,G22)&"" | AE22: =IF(O22="Y",R22,H22)&"" | AF22: =IF(O22="Y",S22,I22)&"" | AG22: =IF(O22="Y",T22,J22)&"" | AH22: =IF(OR(AF22="",Y22<>"Y"),"",INT(IF(O22="Y",V22,L22)/C22)) | AI22: =AB22*IF(O22="Y",X22,N22) | AK22: =IF(AF22="","",HYPERLINK("https://www.lcsc.com/product-detail/"&AF22&".html","open"))
A23: 16 | B23: FB1,FB2 | C23: 2 | D23: 600R@100MHz | E23: Ferrite bead, 600 Ω @ 100 MHz, 300 mA, 0.52 Ω | F23: 0402 | G23: muRata | H23: BLM15AG601SN1D | I23: C76884 | J23: Extended | K23: 1475200 | L23: 1493001 | M23: 100 | N23: 0.0099 | O23: N | Y23: Y | Z23: 0 | AA23: =IF(Y23="Y",C23*$B$4+Z23,0) | AB23: =IF(AA23=0,0,MAX(IF(O23="Y",W23,M23),CEILING(AA23,IF(O23="Y",W23,M23)))) | AC23: =IF(O23="Y",P23,D23)&"" | AD23: =IF(O23="Y",Q23,G23)&"" | AE23: =IF(O23="Y",R23,H23)&"" | AF23: =IF(O23="Y",S23,I23)&"" | AG23: =IF(O23="Y",T23,J23)&"" | AH23: =IF(OR(AF23="",Y23<>"Y"),"",INT(IF(O23="Y",V23,L23)/C23)) | AI23: =AB23*IF(O23="Y",X23,N23) | AK23: =IF(AF23="","",HYPERLINK("https://www.lcsc.com/product-detail/"&AF23&".html","open"))
A24: 17 | B24: J1 | C24: 1 | D24: USB-C | E24: USB-C receptacle, USB 2.0, 16-pin, SMT | F24: USB_C_Receptacle_GCT_USB4110 | G24: Global Connector Technology | H24: USB4110-GF-A | I24: C5143397 | J24: Extended | K24: 0 | L24: 710 | M24: 1 | N24: 1.4914 | O24: N | Y24: Y | Z24: 0 | AA24: =IF(Y24="Y",C24*$B$4+Z24,0) | AB24: =IF(AA24=0,0,MAX(IF(O24="Y",W24,M24),CEILING(AA24,IF(O24="Y",W24,M24)))) | AC24: =IF(O24="Y",P24,D24)&"" | AD24: =IF(O24="Y",Q24,G24)&"" | AE24: =IF(O24="Y",R24,H24)&"" | AF24: =IF(O24="Y",S24,I24)&"" | AG24: =IF(O24="Y",T24,J24)&"" | AH24: =IF(OR(AF24="",Y24<>"Y"),"",INT(IF(O24="Y",V24,L24)/C24)) | AI24: =AB24*IF(O24="Y",X24,N24) | AJ24: LCSC shows 0 in stock but JLCPCB assembly holds 710. For hand assembly buy it from Digi-Key (2073-USB4110-GF-A-1-ND). | AK24: =IF(AF24="","",HYPERLINK("https://www.lcsc.com/product-detail/"&AF24&".html","open"))
A25: 18 | B25: J2 | C25: 1 | D25: BATTERY | E25: JST XA header, 2-pos 2.50 mm, vertical, THT | F25: JST_XA_B02B-XASK-1_1x02_P2.50mm_Vertical | G25: JST | H25: B02B-XASK-1(LF)(SN) | I25: C263753 | J25: Extended | K25: 28050 | L25: 28059 | M25: 10 | N25: 0.0764 | O25: N | Y25: Y | Z25: 0 | AA25: =IF(Y25="Y",C25*$B$4+Z25,0) | AB25: =IF(AA25=0,0,MAX(IF(O25="Y",W25,M25),CEILING(AA25,IF(O25="Y",W25,M25)))) | AC25: =IF(O25="Y",P25,D25)&"" | AD25: =IF(O25="Y",Q25,G25)&"" | AE25: =IF(O25="Y",R25,H25)&"" | AF25: =IF(O25="Y",S25,I25)&"" | AG25: =IF(O25="Y",T25,J25)&"" | AH25: =IF(OR(AF25="",Y25<>"Y"),"",INT(IF(O25="Y",V25,L25)/C25)) | AI25: =AB25*IF(O25="Y",X25,N25) | AJ25: Through-hole. | AK25: =IF(AF25="","",HYPERLINK("https://www.lcsc.com/product-detail/"&AF25&".html","open"))
A26: 19 | B26: J3 | C26: 1 | D26: SWD | E26: Pin header, 1x4, 2.54 mm, vertical, THT | F26: PinHeader_1x04_P2.54mm_Vertical | G26: XFCN | H26: PZ254V-11-04P | I26: C2691448 | J26: Extended | K26: 933760 | L26: 1010306 | M26: 20 | N26: 0.0276 | O26: N | Y26: Y | Z26: 0 | AA26: =IF(Y26="Y",C26*$B$4+Z26,0) | AB26: =IF(AA26=0,0,MAX(IF(O26="Y",W26,M26),CEILING(AA26,IF(O26="Y",W26,M26)))) | AC26: =IF(O26="Y",P26,D26)&"" | AD26: =IF(O26="Y",Q26,G26)&"" | AE26: =IF(O26="Y",R26,H26)&"" | AF26: =IF(O26="Y",S26,I26)&"" | AG26: =IF(O26="Y",T26,J26)&"" | AH26: =IF(OR(AF26="",Y26<>"Y"),"",INT(IF(O26="Y",V26,L26)/C26)) | AI26: =AB26*IF(O26="Y",X26,N26) | AJ26: Through-hole. | AK26: =IF(AF26="","",HYPERLINK("https://www.lcsc.com/product-detail/"&AF26&".html","open"))
A27: 20 | B27: J4 | C27: 1 | D27: VIB_MOTOR | E27: Pin header, 1x2, 2.54 mm, vertical, THT | F27: PinHeader_1x02_P2.54mm_Vertical | G27: XFCN | H27: PZ254V-11-02P | I27: C492401 | J27: Extended | K27: 1151250 | L27: 1161591 | M27: 50 | N27: 0.0184 | O27: N | Y27: Y | Z27: 0 | AA27: =IF(Y27="Y",C27*$B$4+Z27,0) | AB27: =IF(AA27=0,0,MAX(IF(O27="Y",W27,M27),CEILING(AA27,IF(O27="Y",W27,M27)))) | AC27: =IF(O27="Y",P27,D27)&"" | AD27: =IF(O27="Y",Q27,G27)&"" | AE27: =IF(O27="Y",R27,H27)&"" | AF27: =IF(O27="Y",S27,I27)&"" | AG27: =IF(O27="Y",T27,J27)&"" | AH27: =IF(OR(AF27="",Y27<>"Y"),"",INT(IF(O27="Y",V27,L27)/C27)) | AI27: =AB27*IF(O27="Y",X27,N27) | AJ27: Through-hole. The motor itself is not in this BOM. | AK27: =IF(AF27="","",HYPERLINK("https://www.lcsc.com/product-detail/"&AF27&".html","open"))
A28: 21 | B28: J5,J6 | C28: 2 | D28: CSO / CSI | E28: Solder pads for the capacitive-sensor electrode (PCB feature) | F28: SolderWirePad_1x01_SMD_1x2mm | O28: N | Y28: N | Z28: 0 | AA28: =IF(Y28="Y",C28*$B$4+Z28,0) | AB28: =IF(AA28=0,0,MAX(IF(O28="Y",W28,M28),CEILING(AA28,IF(O28="Y",W28,M28)))) | AC28: =IF(O28="Y",P28,D28)&"" | AD28: =IF(O28="Y",Q28,G28)&"" | AE28: =IF(O28="Y",R28,H28)&"" | AF28: =IF(O28="Y",S28,I28)&"" | AG28: =IF(O28="Y",T28,J28)&"" | AH28: =IF(OR(AF28="",Y28<>"Y"),"",INT(IF(O28="Y",V28,L28)/C28)) | AI28: =AB28*IF(O28="Y",X28,N28) | AJ28: Nothing to buy. | AK28: =IF(AF28="","",HYPERLINK("https://www.lcsc.com/product-detail/"&AF28&".html","open"))
A29: 22 | B29: J7 | C29: 1 | D29: PN532 | E29: Socket header, 1x8, 2.54 mm, female, vertical, THT | F29: PinSocket_1x08_P2.54mm_Vertical | G29: JXTCONN | H29: PM2.54-1X8PM-H85 | I29: C42431840 | J29: Extended | K29: 21230 | L29: 21231 | M29: 5 | N29: 0.113 | O29: N | Y29: Y | Z29: 0 | AA29: =IF(Y29="Y",C29*$B$4+Z29,0) | AB29: =IF(AA29=0,0,MAX(IF(O29="Y",W29,M29),CEILING(AA29,IF(O29="Y",W29,M29)))) | AC29: =IF(O29="Y",P29,D29)&"" | AD29: =IF(O29="Y",Q29,G29)&"" | AE29: =IF(O29="Y",R29,H29)&"" | AF29: =IF(O29="Y",S29,I29)&"" | AG29: =IF(O29="Y",T29,J29)&"" | AH29: =IF(OR(AF29="",Y29<>"Y"),"",INT(IF(O29="Y",V29,L29)/C29)) | AI29: =AB29*IF(O29="Y",X29,N29) | AJ29: Through-hole. The PN532 module is not in this BOM. | AK29: =IF(AF29="","",HYPERLINK("https://www.lcsc.com/product-detail/"&AF29&".html","open"))
A30: 23 | B30: L3,L4 | C30: 2 | D30: 470nH | E30: Inductor, wirewound ceramic, 470 nH ±5%, 250 mA, 1.76 Ω | F30: 0805 | G30: muRata | H30: LQW2BASR47J00L | I30: C337959 | J30: Extended | K30: 4980 | L30: 4980 | M30: 5 | N30: 0.1242 | O30: N | Y30: Y | Z30: 0 | AA30: =IF(Y30="Y",C30*$B$4+Z30,0) | AB30: =IF(AA30=0,0,MAX(IF(O30="Y",W30,M30),CEILING(AA30,IF(O30="Y",W30,M30)))) | AC30: =IF(O30="Y",P30,D30)&"" | AD30: =IF(O30="Y",Q30,G30)&"" | AE30: =IF(O30="Y",R30,H30)&"" | AF30: =IF(O30="Y",S30,I30)&"" | AG30: =IF(O30="Y",T30,J30)&"" | AH30: =IF(OR(AF30="",Y30<>"Y"),"",INT(IF(O30="Y",V30,L30)/C30)) | AI30: =AB30*IF(O30="Y",X30,N30) | AJ30: Same rating as the Coilcraft 0805CS-471 in the Digi-Key BOM. The multilayer-ferrite 470 nH parts at LCSC (e.g. TDK MLF2012) have lower DCR but a ferrite core, which is worse for the RF drive. | AK30: =IF(AF30="","",HYPERLINK("https://www.lcsc.com/product-detail/"&AF30&".html","open"))
A31: 24 | B31: Q1 | C31: 1 | D31: AO3400A | E31: MOSFET, N-ch 30 V 5.7 A (motor driver) | F31: SOT-23 | G31: AOS | H31: AO3400A | I31: C20917 | J31: Basic | K31: 681455 | L31: 1074077 | M31: 5 | N31: 0.0853 | O31: N | Y31: Y | Z31: 0 | AA31: =IF(Y31="Y",C31*$B$4+Z31,0) | AB31: =IF(AA31=0,0,MAX(IF(O31="Y",W31,M31),CEILING(AA31,IF(O31="Y",W31,M31)))) | AC31: =IF(O31="Y",P31,D31)&"" | AD31: =IF(O31="Y",Q31,G31)&"" | AE31: =IF(O31="Y",R31,H31)&"" | AF31: =IF(O31="Y",S31,I31)&"" | AG31: =IF(O31="Y",T31,J31)&"" | AH31: =IF(OR(AF31="",Y31<>"Y"),"",INT(IF(O31="Y",V31,L31)/C31)) | AI31: =AB31*IF(O31="Y",X31,N31) | AK31: =IF(AF31="","",HYPERLINK("https://www.lcsc.com/product-detail/"&AF31&".html","open"))
A32: 25 | B32: R1,R2 | C32: 2 | D32: 5.1k | E32: Resistor, 5.1 kΩ ±1% 1/8 W (USB-C CC) | F32: 0805 | G32: UNI-ROYAL | H32: 0805W8F5101T5E | I32: C27834 | J32: Basic | K32: 2477700 | L32: 3573872 | M32: 100 | N32: 0.0056 | O32: N | Y32: Y | Z32: 0 | AA32: =IF(Y32="Y",C32*$B$4+Z32,0) | AB32: =IF(AA32=0,0,MAX(IF(O32="Y",W32,M32),CEILING(AA32,IF(O32="Y",W32,M32)))) | AC32: =IF(O32="Y",P32,D32)&"" | AD32: =IF(O32="Y",Q32,G32)&"" | AE32: =IF(O32="Y",R32,H32)&"" | AF32: =IF(O32="Y",S32,I32)&"" | AG32: =IF(O32="Y",T32,J32)&"" | AH32: =IF(OR(AF32="",Y32<>"Y"),"",INT(IF(O32="Y",V32,L32)/C32)) | AI32: =AB32*IF(O32="Y",X32,N32) | AK32: =IF(AF32="","",HYPERLINK("https://www.lcsc.com/product-detail/"&AF32&".html","open"))
A33: 26 | B33: R3,R4,R5,R9,R10 | C33: 5 | D33: 470R | E33: Resistor, 470 Ω ±1% 1/8 W (LED series) | F33: 0805 | G33: UNI-ROYAL | H33: 0805W8F4700T5E | I33: C17710 | J33: Basic | K33: 2280000 | L33: 2879988 | M33: 100 | N33: 0.0049 | O33: N | Y33: Y | Z33: 0 | AA33: =IF(Y33="Y",C33*$B$4+Z33,0) | AB33: =IF(AA33=0,0,MAX(IF(O33="Y",W33,M33),CEILING(AA33,IF(O33="Y",W33,M33)))) | AC33: =IF(O33="Y",P33,D33)&"" | AD33: =IF(O33="Y",Q33,G33)&"" | AE33: =IF(O33="Y",R33,H33)&"" | AF33: =IF(O33="Y",S33,I33)&"" | AG33: =IF(O33="Y",T33,J33)&"" | AH33: =IF(OR(AF33="",Y33<>"Y"),"",INT(IF(O33="Y",V33,L33)/C33)) | AI33: =AB33*IF(O33="Y",X33,N33) | AK33: =IF(AF33="","",HYPERLINK("https://www.lcsc.com/product-detail/"&AF33&".html","open"))
A34: 27 | B34: R6 | C34: 1 | D34: 1k | E34: Resistor, ±1% 1/8 W (MCP73833 PROG: sets charge current) | F34: 0805 | G34: UNI-ROYAL | H34: 0805W8F1001T5E | I34: C17513 | J34: Basic | K34: 27482800 | L34: 31829451 | M34: 100 | N34: 0.0041 | O34: N | P34: 2k | Q34: UNI-ROYAL | R34: 0805W8F2001T5E | S34: C17604 | T34: Basic | U34: 4433300 | V34: 5690088 | W34: 100 | X34: 0.0039 | Y34: Y | Z34: 0 | AA34: =IF(Y34="Y",C34*$B$4+Z34,0) | AB34: =IF(AA34=0,0,MAX(IF(O34="Y",W34,M34),CEILING(AA34,IF(O34="Y",W34,M34)))) | AC34: =IF(O34="Y",P34,D34)&"" | AD34: =IF(O34="Y",Q34,G34)&"" | AE34: =IF(O34="Y",R34,H34)&"" | AF34: =IF(O34="Y",S34,I34)&"" | AG34: =IF(O34="Y",T34,J34)&"" | AH34: =IF(OR(AF34="",Y34<>"Y"),"",INT(IF(O34="Y",V34,L34)/C34)) | AI34: =AB34*IF(O34="Y",X34,N34) | AJ34: 1 kΩ = 1 A charge current, more than a USB-C sink with 5.1 kΩ Rd may draw (500 mA). Set Use alternate = Y for 2 kΩ (500 mA) after changing the schematic. | AK34: =IF(AF34="","",HYPERLINK("https://www.lcsc.com/product-detail/"&AF34&".html","open"))
A35: 28 | B35: R7,R8,R11,R12,R20 | C35: 5 | D35: 10k | E35: Resistor, 10 kΩ ±1% 1/8 W | F35: 0805 | G35: UNI-ROYAL | H35: 0805W8F1002T5E | I35: C17414 | J35: Basic | K35: 44415400 | L35: 51391005 | M35: 100 | N35: 0.0039 | O35: N | Y35: Y | Z35: 0 | AA35: =IF(Y35="Y",C35*$B$4+Z35,0) | AB35: =IF(AA35=0,0,MAX(IF(O35="Y",W35,M35),CEILING(AA35,IF(O35="Y",W35,M35)))) | AC35: =IF(O35="Y",P35,D35)&"" | AD35: =IF(O35="Y",Q35,G35)&"" | AE35: =IF(O35="Y",R35,H35)&"" | AF35: =IF(O35="Y",S35,I35)&"" | AG35: =IF(O35="Y",T35,J35)&"" | AH35: =IF(OR(AF35="",Y35<>"Y"),"",INT(IF(O35="Y",V35,L35)/C35)) | AI35: =AB35*IF(O35="Y",X35,N35) | AK35: =IF(AF35="","",HYPERLINK("https://www.lcsc.com/product-detail/"&AF35&".html","open"))
A36: 29 | B36: R15 | C36: 1 | D36: 1.5k | E36: Resistor, 1.5 kΩ ±1% 1/8 W (antenna damping) | F36: 0805 | G36: UNI-ROYAL | H36: 0805W8F1501T5E | I36: C4310 | J36: Basic | K36: 445400 | L36: 832480 | M36: 100 | N36: 0.0035 | O36: N | Y36: Y | Z36: 0 | AA36: =IF(Y36="Y",C36*$B$4+Z36,0) | AB36: =IF(AA36=0,0,MAX(IF(O36="Y",W36,M36),CEILING(AA36,IF(O36="Y",W36,M36)))) | AC36: =IF(O36="Y",P36,D36)&"" | AD36: =IF(O36="Y",Q36,G36)&"" | AE36: =IF(O36="Y",R36,H36)&"" | AF36: =IF(O36="Y",S36,I36)&"" | AG36: =IF(O36="Y",T36,J36)&"" | AH36: =IF(OR(AF36="",Y36<>"Y"),"",INT(IF(O36="Y",V36,L36)/C36)) | AI36: =AB36*IF(O36="Y",X36,N36) | AJ36: May change during antenna tuning. | AK36: =IF(AF36="","",HYPERLINK("https://www.lcsc.com/product-detail/"&AF36&".html","open"))
A37: 30 | B37: R16,R18,R19 | C37: 3 | D37: 4.7M | E37: Resistor, 4.7 MΩ ±1% 1/8 W (battery and VBUS dividers) | F37: 0805 | G37: UNI-ROYAL | H37: 0805W8F4704T5E | I37: C17674 | J37: Extended | K37: 76200 | L37: 77104 | M37: 100 | N37: 0.003 | O37: N | Y37: Y | Z37: 0 | AA37: =IF(Y37="Y",C37*$B$4+Z37,0) | AB37: =IF(AA37=0,0,MAX(IF(O37="Y",W37,M37),CEILING(AA37,IF(O37="Y",W37,M37)))) | AC37: =IF(O37="Y",P37,D37)&"" | AD37: =IF(O37="Y",Q37,G37)&"" | AE37: =IF(O37="Y",R37,H37)&"" | AF37: =IF(O37="Y",S37,I37)&"" | AG37: =IF(O37="Y",T37,J37)&"" | AH37: =IF(OR(AF37="",Y37<>"Y"),"",INT(IF(O37="Y",V37,L37)/C37)) | AI37: =AB37*IF(O37="Y",X37,N37) | AK37: =IF(AF37="","",HYPERLINK("https://www.lcsc.com/product-detail/"&AF37&".html","open"))
A38: 31 | B38: R17 | C38: 1 | D38: 2.7M | E38: Resistor, 2.7 MΩ ±1% 1/8 W (battery divider low leg) | F38: 0805 | G38: UNI-ROYAL | H38: 0805W8F2704T5E | I38: C17531 | J38: Extended | K38: 29200 | L38: 29539 | M38: 100 | N38: 0.0048 | O38: N | Y38: Y | Z38: 0 | AA38: =IF(Y38="Y",C38*$B$4+Z38,0) | AB38: =IF(AA38=0,0,MAX(IF(O38="Y",W38,M38),CEILING(AA38,IF(O38="Y",W38,M38)))) | AC38: =IF(O38="Y",P38,D38)&"" | AD38: =IF(O38="Y",Q38,G38)&"" | AE38: =IF(O38="Y",R38,H38)&"" | AF38: =IF(O38="Y",S38,I38)&"" | AG38: =IF(O38="Y",T38,J38)&"" | AH38: =IF(OR(AF38="",Y38<>"Y"),"",INT(IF(O38="Y",V38,L38)/C38)) | AI38: =AB38*IF(O38="Y",X38,N38) | AK38: =IF(AF38="","",HYPERLINK("https://www.lcsc.com/product-detail/"&AF38&".html","open"))
A39: 32 | B39: R21,R22 | C39: 2 | D39: 0 | E39: Resistor, 0 Ω jumper (antenna feed) | F39: 0805 | G39: UNI-ROYAL | H39: 0805W8F0000T5E | I39: C17477 | J39: Basic | K39: 5411400 | L39: 7103041 | M39: 100 | N39: 0.0045 | O39: N | Y39: Y | Z39: 0 | AA39: =IF(Y39="Y",C39*$B$4+Z39,0) | AB39: =IF(AA39=0,0,MAX(IF(O39="Y",W39,M39),CEILING(AA39,IF(O39="Y",W39,M39)))) | AC39: =IF(O39="Y",P39,D39)&"" | AD39: =IF(O39="Y",Q39,G39)&"" | AE39: =IF(O39="Y",R39,H39)&"" | AF39: =IF(O39="Y",S39,I39)&"" | AG39: =IF(O39="Y",T39,J39)&"" | AH39: =IF(OR(AF39="",Y39<>"Y"),"",INT(IF(O39="Y",V39,L39)/C39)) | AI39: =AB39*IF(O39="Y",X39,N39) | AK39: =IF(AF39="","",HYPERLINK("https://www.lcsc.com/product-detail/"&AF39&".html","open"))
A40: 33 | B40: SW1,SW2,SW3 | C40: 3 | D40: RST / BOOT0 / POWER | E40: Tactile switch, SPST-NO, 250 gf, 2.5 mm height, SMT | F40: SW_Tactile_SPST_NO_Straight_CK_PTS636Sx25SMTRLFS | G40: C&K | H40: PTS636SK25SMTRLFS | I40: C2689642 | J40: Extended | K40: 3520 | L40: 3524 | M40: 5 | N40: 0.2615 | O40: N | Y40: Y | Z40: 0 | AA40: =IF(Y40="Y",C40*$B$4+Z40,0) | AB40: =IF(AA40=0,0,MAX(IF(O40="Y",W40,M40),CEILING(AA40,IF(O40="Y",W40,M40)))) | AC40: =IF(O40="Y",P40,D40)&"" | AD40: =IF(O40="Y",Q40,G40)&"" | AE40: =IF(O40="Y",R40,H40)&"" | AF40: =IF(O40="Y",S40,I40)&"" | AG40: =IF(O40="Y",T40,J40)&"" | AH40: =IF(OR(AF40="",Y40<>"Y"),"",INT(IF(O40="Y",V40,L40)/C40)) | AI40: =AB40*IF(O40="Y",X40,N40) | AJ40: PTS636 SK25 (250 gf) because the SM25 (180 gf, C2799946) is out of stock at LCSC. Same footprint, slightly stiffer press. | AK40: =IF(AF40="","",HYPERLINK("https://www.lcsc.com/product-detail/"&AF40&".html","open"))
A41: 34 | B41: TH1 | C41: 1 | D41: 10k NTC | E41: NTC thermistor, 10 kΩ ±5%, B25/85 = 3977 K, leaded | F41: R_Axial_DIN0204_L3.6mm_D1.6mm_P1.90mm_Vertical | G41: VISHAY | H41: NTCLE100E3103JB0 | I41: C141588 | J41: Extended | K41: 266 | L41: 266 | M41: 1 | N41: 0.6261 | O41: N | Y41: Y | Z41: 0 | AA41: =IF(Y41="Y",C41*$B$4+Z41,0) | AB41: =IF(AA41=0,0,MAX(IF(O41="Y",W41,M41),CEILING(AA41,IF(O41="Y",W41,M41)))) | AC41: =IF(O41="Y",P41,D41)&"" | AD41: =IF(O41="Y",Q41,G41)&"" | AE41: =IF(O41="Y",R41,H41)&"" | AF41: =IF(O41="Y",S41,I41)&"" | AG41: =IF(O41="Y",T41,J41)&"" | AH41: =IF(OR(AF41="",Y41<>"Y"),"",INT(IF(O41="Y",V41,L41)/C41)) | AI41: =AB41*IF(O41="Y",X41,N41) | AJ41: Through-hole; bend the leads to the 1.9 mm footprint pitch. | AK41: =IF(AF41="","",HYPERLINK("https://www.lcsc.com/product-detail/"&AF41&".html","open"))
A42: 35 | B42: U1 | C42: 1 | D42: STM32L432KBU6 | E42: MCU, Cortex-M4F 80 MHz, 128 kB flash, 64 kB RAM | F42: QFN-32-1EP_5x5mm_P0.5mm_EP3.45x3.45mm | G42: ST | H42: STM32L432KBU6 | I42: C2928224 | J42: Extended | M42: 1 | O42: N | Y42: Y | Z42: 0 | AA42: =IF(Y42="Y",C42*$B$4+Z42,0) | AB42: =IF(AA42=0,0,MAX(IF(O42="Y",W42,M42),CEILING(AA42,IF(O42="Y",W42,M42)))) | AC42: =IF(O42="Y",P42,D42)&"" | AD42: =IF(O42="Y",Q42,G42)&"" | AE42: =IF(O42="Y",R42,H42)&"" | AF42: =IF(O42="Y",S42,I42)&"" | AG42: =IF(O42="Y",T42,J42)&"" | AH42: =IF(OR(AF42="",Y42<>"Y"),"",INT(IF(O42="Y",V42,L42)/C42)) | AI42: =AB42*IF(O42="Y",X42,N42) | AJ42: 128 kB part, as on the schematic and in production/bom.csv; the firmware keeps code (72 kB) and the log (56 kB) within 128 kB. Stock, price and JLCPCB library type not re-read for this part: check lcsc.com before ordering (cost counts 0 until then). | AK42: =IF(AF42="","",HYPERLINK("https://www.lcsc.com/product-detail/"&AF42&".html","open"))
...

Sheet JLCPCB_BOM
A1: Comment | B1: Designator | C1: Footprint | D1: LCSC Part #
A2: =BOM!AC8 | B2: =BOM!B8 | C2: =BOM!F8 | D2: =BOM!AF8
A3: =BOM!AC9 | B3: =BOM!B9 | C3: =BOM!F9 | D3: =BOM!AF9
A4: =BOM!AC10 | B4: =BOM!B10 | C4: =BOM!F10 | D4: =BOM!AF10
A5: =BOM!AC11 | B5: =BOM!B11 | C5: =BOM!F11 | D5: =BOM!AF11
A6: =BOM!AC12 | B6: =BOM!B12 | C6: =BOM!F12 | D6: =BOM!AF12
A7: =BOM!AC13 | B7: =BOM!B13 | C7: =BOM!F13 | D7: =BOM!AF13
A8: =BOM!AC14 | B8: =BOM!B14 | C8: =BOM!F14 | D8: =BOM!AF14
A9: =BOM!AC15 | B9: =BOM!B15 | C9: =BOM!F15 | D9: =BOM!AF15
A10: =BOM!AC16 | B10: =BOM!B16 | C10: =BOM!F16 | D10: =BOM!AF16
A11: =BOM!AC17 | B11: =BOM!B17 | C11: =BOM!F17 | D11: =BOM!AF17
A12: =BOM!AC18 | B12: =BOM!B18 | C12: =BOM!F18 | D12: =BOM!AF18
A13: =BOM!AC19 | B13: =BOM!B19 | C13: =BOM!F19 | D13: =BOM!AF19
... A21: =BOM!AC27 | B21: =BOM!B27 | C21: =BOM!F27 | D21: =BOM!AF27
A22: =BOM!AC29 | B22: =BOM!B29 | C22: =BOM!F29 | D22: =BOM!AF29
A23: =BOM!AC30 | B23: =BOM!B30 | C23: =BOM!F30 | D23: =BOM!AF30
A24: =BOM!AC31 | B24: =BOM!B31 | C24: =BOM!F31 | D24: =BOM!AF31
A25: =BOM!AC32 | B25: =BOM!B32 | C25: =BOM!F32 | D25: =BOM!AF32
A26: =BOM!AC33 | B26: =BOM!B33 | C26: =BOM!F33 | D26: =BOM!AF33
A27: =BOM!AC34 | B27: =BOM!B34 | C27: =BOM!F34 | D27: =BOM!AF34
A28: =BOM!AC35 | B28: =BOM!B35 | C28: =BOM!F35 | D28: =BOM!AF35
A29: =BOM!AC36 | B29: =BOM!B36 | C29: =BOM!F36 | D29: =BOM!AF36
A30: =BOM!AC37 | B30: =BOM!B37 | C30: =BOM!F37 | D30: =BOM!AF37
A31: =BOM!AC38 | B31: =BOM!B38 | C31: =BOM!F38 | D31: =BOM!AF38
A32: =BOM!AC39 | B32: =BOM!B39 | C32: =BOM!F39 | D32: =BOM!AF39
A33: =BOM!AC40 | B33: =BOM!B40 | C33: =BOM!F40 | D33: =BOM!AF40
... A41: =BOM!AC48 | B41: =BOM!B48 | C41: =BOM!F48 | D41: =BOM!AF48

Sheet LCSC_Order
A1: Quantity | B1: LCSC Part Number | C1: Manufacturer Part Number | D1: Manufacturer | E1: Customer Reference
A2: =BOM!AB8 | B2: =BOM!AF8 | C2: =BOM!AE8 | D2: =BOM!AD8 | E2: =BOM!B8
A3: =BOM!AB9 | B3: =BOM!AF9 | C3: =BOM!AE9 | D3: =BOM!AD9 | E3: =BOM!B9
A4: =BOM!AB10 | B4: =BOM!AF10 | C4: =BOM!AE10 | D4: =BOM!AD10 | E4: =BOM!B10
A5: =BOM!AB11 | B5: =BOM!AF11 | C5: =BOM!AE11 | D5: =BOM!AD11 | E5: =BOM!B11
A6: =BOM!AB12 | B6: =BOM!AF12 | C6: =BOM!AE12 | D6: =BOM!AD12 | E6: =BOM!B12
A7: =BOM!AB13 | B7: =BOM!AF13 | C7: =BOM!AE13 | D7: =BOM!AD13 | E7: =BOM!B13
A8: =BOM!AB14 | B8: =BOM!AF14 | C8: =BOM!AE14 | D8: =BOM!AD14 | E8: =BOM!B14
A9: =BOM!AB15 | B9: =BOM!AF15 | C9: =BOM!AE15 | D9: =BOM!AD15 | E9: =BOM!B15
A10: =BOM!AB16 | B10: =BOM!AF16 | C10: =BOM!AE16 | D10: =BOM!AD16 | E10: =BOM!B16
A11: =BOM!AB17 | B11: =BOM!AF17 | C11: =BOM!AE17 | D11: =BOM!AD17 | E11: =BOM!B17
A12: =BOM!AB18 | B12: =BOM!AF18 | C12: =BOM!AE18 | D12: =BOM!AD18 | E12: =BOM!B18
A13: =BOM!AB19 | B13: =BOM!AF19 | C13: =BOM!AE19 | D13: =BOM!AD19 | E13: =BOM!B19
... A21: =BOM!AB27 | B21: =BOM!AF27 | C21: =BOM!AE27 | D21: =BOM!AD27 | E21: =BOM!B27
A22: =BOM!AB29 | B22: =BOM!AF29 | C22: =BOM!AE29 | D22: =BOM!AD29 | E22: =BOM!B29
A23: =BOM!AB30 | B23: =BOM!AF30 | C23: =BOM!AE30 | D23: =BOM!AD30 | E23: =BOM!B30
A24: =BOM!AB31 | B24: =BOM!AF31 | C24: =BOM!AE31 | D24: =BOM!AD31 | E24: =BOM!B31
A25: =BOM!AB32 | B25: =BOM!AF32 | C25: =BOM!AE32 | D25: =BOM!AD32 | E25: =BOM!B32
A26: =BOM!AB33 | B26: =BOM!AF33 | C26: =BOM!AE33 | D26: =BOM!AD33 | E26: =BOM!B33
A27: =BOM!AB34 | B27: =BOM!AF34 | C27: =BOM!AE34 | D27: =BOM!AD34 | E27: =BOM!B34
A28: =BOM!AB35 | B28: =BOM!AF35 | C28: =BOM!AE35 | D28: =BOM!AD35 | E28: =BOM!B35
A29: =BOM!AB36 | B29: =BOM!AF36 | C29: =BOM!AE36 | D29: =BOM!AD36 | E29: =BOM!B36
A30: =BOM!AB37 | B30: =BOM!AF37 | C30: =BOM!AE37 | D30: =BOM!AD37 | E30: =BOM!B37
A31: =BOM!AB38 | B31: =BOM!AF38 | C31: =BOM!AE38 | D31: =BOM!AD38 | E31: =BOM!B38
A32: =BOM!AB39 | B32: =BOM!AF39 | C32: =BOM!AE39 | D32: =BOM!AD39 | E32: =BOM!B39
A33: =BOM!AB40 | B33: =BOM!AF40 | C33: =BOM!AE40 | D33: =BOM!AD40 | E33: =BOM!B40
... A41: =BOM!AB48 | B41: =BOM!AF48 | C41: =BOM!AE48 | D41: =BOM!AD48 | E41: =BOM!B48
A42: =BOM!AB50 | B42: =BOM!AF50 | C42: =BOM!AE50 | D42: =BOM!AD50 | E42: =BOM!B50
A43: =BOM!AB51 | B43: =BOM!AF51 | C43: =BOM!AE51 | D43: =BOM!AD51 | E43: =BOM!B51
